Workbook

Sheet Assumptions
B1: MAQSAD ROI model: assumptions and inputs
B2: Blue = entered input; black = formula; green = link to another sheet. The Status column says whether a value is measured, verified, confirmed by the team or a Taxmin (assumption). All amounts in UZS. Synthetic model metrics are reference only; do not treat as pilot accuracy. The recovered-loss benefit stays unavailable until today's baseline detection rate is measured.
A4: # | B4: Parameter | C4: Pessimistic | D4: Base | E4: Optimistic | F4: Unit | G4: Status | H4: Source / note
B5: A. Visit savings
A6: 1 | B6: Number of loans monitored (N) | C6: 1540 | D6: =C6 -> 1540 | E6: =C6 -> 1540 | F6: loans | G6: Taxmin: one-branch pilot (derived from brief data) | H6: Taxmin: pilot runs in ONE branch. MKBANK ~250,000 business clients / 162 branches = ~1,543 per branch (Erste Asset Management data quoted in docs/brief.md), rounded to 1,540. Upper bound: not every client holds a preferential loan. Replace with the branch's actual number of monitored loans in pilot month 1. (Earlier versions used 1,000 and then 5,000 = synthetic portfolio size, which is not the pilot scope.)
A7: 2 | B7: Scheduled visits per year (per loan) | C7: 2 | D7: =(C7+E7)/2 -> 3 | E7: 4 | F7: visits/year | G7: Taxmin: no public source found | H7: Taxmin: no public source found; to be replaced with MKBANK data in the pilot: 2-4 times a year for small-business loans. 'Base' = midpoint of the range (assumption). The first visit within 30 days of disbursement is not included (conservative). || SOURCE CHECK (10 Oct 2026): No public source found; confirm with MKBANK.
A8: 3 | B8: Cost to the bank of one visit | C8: 100000 | D8: =(C8+E8)/2 -> 200000 | E8: 300000 | F8: UZS/visit | G8: Taxmin: no public source found | H8: Taxmin: no public source found; to be replaced with MKBANK data in the pilot: roughly 100,000 - 300,000 UZS (higher in remote regions). MUST be replaced with MKBANK's internal figure or presented as an illustrative assumption. || SOURCE CHECK (10 Oct 2026): No public source found; confirm with MKBANK. The phrase 'internal calculations of banks' in the original answer cannot be checked.
A9: 4 | B9: Share of loans visited in person with Maqsad | C9: 0.5 | D9: 0.2 | E9: 0.2 | F9: % of portfolio | G9: Assumption (Base/Optimistic: brief); Pessimistic: Taxmin | H9: Base/Optimistic: the 20% visit budget from the brief (recall@20% measured at this budget); the other 80% are checked remotely. Pessimistic (Taxmin): the regulator or bank policy still requires physical visits to 50% of loans, so only half of today's visits are saved. To be confirmed with MKBANK / CBU rules and validated in pilot month 2.
B10: B. Early-detected losses
A11: 5 | B11: Share of the portfolio with misused loans | C11: 0.03 | D11: =(C11+E11)/2 -> 0.05 | E11: 0.07 | F11: % of portfolio | G11: Taxmin: no public source found | H11: Taxmin: no public source found; to be replaced with MKBANK data in the pilot: 3% to 7%. Pessimistic = 3%, optimistic = 7%, base = 5% (midpoint). MUST be replaced with MKBANK statistics or presented as an illustrative assumption. || SOURCE CHECK (10 Oct 2026): No public source found; confirm with MKBANK. 68 bn / 2,500 cases is a count of cases, not a share of the portfolio.
A12: 6 | B12: Misused amount found in regional inspections | C12: 68000000000 | D12: =C12 -> 68000000000 | E12: =C12 -> 68000000000 | F12: UZS | G12: Source: anhor.uz | H12: 68 bn UZS across 2,500 cases (President's meeting, anhor.uz/ru/news/heads-of-banks). Re-check against the source before putting it in the deck.
A13: 7 | B13: Number of cases found | C13: 2500 | D13: =C13 -> 2500 | E13: =C13 -> 2500 | F13: cases | G13: Source: anhor.uz | H13: Same source. This is a nationwide regional inspection, not MKBANK-specific.
A14: 8 | B14: Average misused amount per case | C14: =C12/C13 -> 27200000 | D14: =D12/D13 -> 27200000 | E14: =E12/E13 -> 27200000 | F14: UZS/case | G14: Calculated | H14: Calculation: 68 bn / 2,500. Assumption: MKBANK cases are similar.
A15: 9 | B15: Maqsad detection rate (recall@20%) | C15: 0.728 | D15: 0.782 | E15: 0.832 | F15: % of cases | G15: Measured (final holdout), synthetic | H15: Holdout point estimate from the final synthetic evaluation (docs/metrics.md): recall@20% = 78.2%; supplier-clustered 95% CI = 72.8%-83.2%. This is not live-bank accuracy. Baseline current-method catch rate is still required before estimating incremental benefit.
A16: 10 | B16: Share of the amount recovered if detected early | C16: 1 | D16: =C16 -> 1 | E16: =C16 -> 1 | F16: % of amount | G16: Upper bound, not supported | H16: Taxmin: no public source found; to be replaced with MKBANK data in the pilot: if detected early the bank recovers 100% of the misused amount. Note: this is the recovery rule; Maqsad's incremental benefit is the difference versus today's method (see next row). || SOURCE CHECK (10 Oct 2026): Public rules only give banks the RIGHT to recover early (lex.uz/uz/docs/-7750738, art. 37; finlit.uz Q&A by the Central Bank). Full recovery is not guaranteed; treat 100% as an upper bound.
A17: 11 | B17: Share of cases today's method already catches (baseline) | D17: =IF(C17="","",C17) | E17: =IF(C17="","",C17) | F17: % of cases | G17: Pilot month 1 measurement (not available now) | H17: Share of misused cases that today's method already catches. No data exists yet: it comes from the trainer's month-1 measurement in the pilot or from MKBANK. Left blank on purpose; until then the recovered-loss benefit stays 'not entered' and the deck uses the comparison with the simple rule (ROI sheet, section H).
A18: 12 | B18: Penalty share (NOT counted in benefit) | C18: 0.1 | D18: =(C18+E18)/2 -> 0.175 | E18: 0.25 | F18: % of amount | G18: Taxmin: no public source found | H18: Taxmin: no public source found; to be replaced with MKBANK data in the pilot: one-time penalty of 10-25% of the misused amount. It is not confirmed that the penalty goes to the bank, so it is excluded from the benefit (conservative). || SOURCE CHECK (10 Oct 2026): No public source found; confirm with MKBANK. Not used in the calculation.
B19: C. Pilot costs
A20: 13 | B20: AI/ML engineer hourly rate | C20: 90000 | D20: =C20 -> 90000 | E20: =C20 -> 90000 | F20: UZS/hour | G20: Taxmin: likely low | H20: Taxmin; confirm against real rates. || SOURCE CHECK (10 Oct 2026): spot.uz (2024-05-22): average maximum offered developer salary 23.4 M UZS/month, minimum 15.6 M (about 93k-139k UZS/hour at 168 h/month, my conversion). 80-90k/hour is at or below the low end.
A21: 14 | B21: Backend/Frontend developer hourly rate | C21: 80000 | D21: =C21 -> 80000 | E21: =C21 -> 80000 | F21: UZS/hour | G21: Taxmin: likely low | H21: Taxmin; confirm against real rates. || SOURCE CHECK (10 Oct 2026): spot.uz (2024-05-22): average maximum offered developer salary 23.4 M UZS/month, minimum 15.6 M (about 93k-139k UZS/hour at 168 h/month, my conversion). 80-90k/hour is at or below the low end.
A22: 15 | B22: Trainer / business analyst hourly rate | C22: 60000 | D22: =C22 -> 60000 | E22: =C22 -> 60000 | F22: UZS/hour | G22: Taxmin: likely low | H22: Taxmin; confirm against real rates. || SOURCE CHECK (10 Oct 2026): spot.uz (2024-05-22): average maximum offered developer salary 23.4 M UZS/month, minimum 15.6 M (about 93k-139k UZS/hour at 168 h/month, my conversion). 80-90k/hour is at or below the low end.
A23: 16 | B23: Pilot hours: AI/ML engineer | C23: 320 | D23: 220 | E23: 140 | F23: hours | G23: Taxmin: team plan (Dilshodbek, 11 Oct) | H23: One-time: installation, adapting the model to bank data. AI/ML engineer only. Base 220 h = month 1: 120 (connect bank tables, retrain and evaluate on historical loans, retrain CLIP on real photos), month 2: 60 (monitoring, threshold tuning, fixes from officer feedback), month 3: 40 (measurement, report, handover). Pessimistic 320 = messy or incomplete bank data, few fraud signals in history; Optimistic 140 = clean data close to the synthetic portfolio. Biggest uncertainty: quality of bank data.
A24: 17 | B24: Pilot hours: Backend/Frontend | C24: 520 | D24: 340 | E24: 240 | F24: hours | G24: Confirmed by Oybek (11 Oct) | H24: One-time: on-prem installation and app work. Base ~340 h (confirmed by Oybek) (his table sums to 344) = month 1: 168 (install on bank server, bank data adapter, local LLM with GPU, SSO/roles, audit to bank DB, historical test run), month 2: 96 (support, officer-feedback changes, training, monitoring), month 3: 80 (result report, documents). Pessimistic ~520 = complex data connection, many security requirements, GPU server delayed; Optimistic ~240. About 500 h in 3 months = 1 FTE (his assumption). Includes 12 h of officer training, so do not count the same training again under the trainer row.
A25: 18 | B25: Pilot hours: Trainer / business analyst | C25: 240 | D25: 160 | E25: 100 | F25: hours | G25: Taxmin: team plan (trainer, 11 Oct) | H25: Trainer / business analyst. Base 160 h = month 1: 70 (learn the process, measure today's method: visits per year, cost per visit, share of misuse found now, training materials, KPI plan), month 2: 50 (staff training, weekly feedback), month 3: 40 (compare results, update the ROI, final report). Pessimistic 240, Optimistic 100. Month 1 fills the empty inputs of this model (Assumptions rows 7, 8, 17): the first task of the pilot. Overlap check: Oybek's plan also has 12 h of officer training; confirm that the trainer's month-2 training is not the same sessions counted twice.
A26: 19 | B26: GPU server / on-prem hardware (one-time) | C26: 142000000 | D26: =(C26+E26)/2 -> 118500000 | E26: 95000000 | F26: UZS | G26: Partly verified (GPU only) | H26: Taxmin: no public source found; to be replaced with MKBANK data in the pilot: enough for a 1-branch or 1-district pilot (1x RTX 6000 Ada or RTX 4090 workstation, 64 GB RAM, 2 TB NVMe), about USD 8,000-12,000 = 95-142 M UZS. Pessimistic = expensive end. Confirm against market prices. || SOURCE CHECK (10 Oct 2026): RTX 6000 Ada alone: MSRP USD 6,800 (computerbase.de, 2023); lowest US retail price USD 7,499 as of Oct 2026 (gpuprix.com). The USD 8,000-12,000 whole-server range is not sourced; the low end leaves almost nothing for CPU/RAM/SSD/chassis, so the pessimistic value is more realistic.
A27: 20 | B27: People, support (annual) | C27: 57600000 | D27: =C27 -> 57600000 | E27: =C27 -> 57600000 | F27: UZS/year | G27: Taxmin: no public source found | H27: Taxmin: no public source found; to be replaced with MKBANK data in the pilot: 57,600,000 UZS/year. It is unknown which role and how many hours this comes from; clarify before the deck. || SOURCE CHECK (10 Oct 2026): No public source found; confirm with MKBANK. Role and hours behind 57.6 M are unknown.
A28: 21 | B28: Antivirus, security, certificates, SIEM (annual) | C28: 15000000 | D28: =(C28+E28)/2 -> 12500000 | E28: 10000000 | F28: UZS/year | G28: Taxmin: no public source found | H28: Taxmin: no public source found; to be replaced with MKBANK data in the pilot: about 10-15 M UZS/year. Pessimistic = expensive end. Datasets/models with open licences have no separate fee (see data/README.md). || SOURCE CHECK (10 Oct 2026): No public source found; confirm with MKBANK.
A29: 22 | B29: LLM cost per draft report (USD) | C29: 0.0125 | D29: =D70 -> 0.00687 | E29: =E69 -> 0.003435 | F29: USD/check | G29: Calculated from official price, measured tokens (n=3) | H29: Pessimistic = earlier stress value (higher-priced model, GPT-4o public price, 1,000+1,000 tokens = USD 0.0125). Base = Gemini 3.6 Flash at the 2027 price with measured tokens (~1,230 in / ~670 out, production logs, n=3) = USD 0.0069; Optimistic = the same at the 2026 price = USD 0.0034. The prototype actually runs on the free tier (USD 0 spent). Production would use a local LLM on the bank server, so this API price is only the prototype/benchmark cost. Row 58 holds the logged cost for reference only. Counted in the ROI only for infrastructure options 2-3 (external API); option 1 uses a local LLM, so its API cost is 0.
A30: 23 | B30: Exchange rate: 1 USD = ? UZS | C30: 11846.57 | D30: =C30 -> 11846.57 | E30: =C30 -> 11846.57 | F30: UZS/USD | G30: cbu.uz 08.10.2026 (accepted by team) | H30: cbu.uz official rate dated 08.10.2026: USD = 11,846.57 (read via onmap.uz mirror). The team accepted the 08.10.2026 rate for the deck; the 10-11 Oct rate was not used. Earlier values: 11,808.76 on 01.10.2026; 11,900 original estimate.
A31: 24 | B31: Remote checks per year (per loan) | C31: =C7 -> 2 | D31: =D7 -> 3 | E31: =E7 -> 4 | F31: checks/year | G31: Assumption | H31: Assumption: remote check frequency equals today's visit frequency.
B33: D. Model performance, final holdout (reference only; not used in formulas)
A34: 32 | B34: Maqsad model: share of fraud caught at 20% visit budget | D34: 0.782 | F34: recall@20% | G34: Measured (final holdout), synthetic | H34: Source: Dilshodbek, docs/metrics.md. Point estimate; 95% CI 72.8-83.2%.
A35: 33 | B35: Simple rule baseline | D35: 0.274 | F35: recall@20% | G35: Measured (final holdout), synthetic | H35: Holdout graded-rule baseline: recall@20% = 27.4%. Model and simple-rule comparison use the same synthetic holdout and 20% inspection budget.
A36: 34 | B36: Random selection | D36: 0.2 | F36: recall@20% | G36: Measured (final holdout), synthetic | H36: Expected recall at a 20% budget under random selection. Synthetic reference only.
A37: 35 | B37: By typology T1: fast cash-out | D37: 0.99 | F37: recall@20% | G37: Measured (final holdout), synthetic | H37: Source: Dilshodbek, docs/metrics.md. Strongest type.
A38: 36 | B38: By typology T2: supplier ring | D38: 0.93 | F38: recall@20% | G38: Measured (final holdout), synthetic | H38: Source: Dilshodbek, docs/metrics.md.
A39: 37 | B39: By typology T3: asset resale | D39: 0.57 | F39: recall@20% | G39: Measured (final holdout), synthetic | H39: Holdout recall@20% = 56.9%. Weaker group; 21 T3 resale cases had not yet happened at snapshot and were counted as positives.
A40: 38 | B40: By typology T4: fake invoice | D40: 0.45 | F40: recall@20% | G40: Measured (final holdout), synthetic | H40: Holdout recall@20% = 45.4%. Weakest typology in the final synthetic holdout; pilot performance may differ.
B42: DATASET / METRICS CONTEXT
B43: Train workbook | H43: 5,000 loans; 550 synthetic fraud labels (11%). Train/CV only.
...

Sheet ROI
B1: ROI calculation (annual, UZS)
B2: Results use only the values entered. A missing input shows 'not entered'.
B4: Metric | C4: Pessimistic | D4: Base | E4: Optimistic | F4: Formula / note
B5: A. Visit savings
B6: Number of loans (N) | C6: =Assumptions!C6 -> 1540 | D6: =Assumptions!D6 -> 1540 | E6: =Assumptions!E6 -> 1540 | F6: Assumptions
B7: Current visits per year | C7: =C6*Assumptions!C7 -> 3080 | D7: =D6*Assumptions!D7 -> 4620 | E7: =E6*Assumptions!E7 -> 6160 | F7: N x visits per year
B8: Visits with Maqsad | C8: =C7*Assumptions!C9 -> 1540 | D8: =D7*Assumptions!D9 -> 924 | E8: =E7*Assumptions!E9 -> 1232 | F8: Current visits x share visited
B9: Visits saved | C9: =C7-C8 -> 1540 | D9: =D7-D8 -> 3696 | E9: =E7-E8 -> 4928 | F9: Current - with Maqsad
B10: Cost of one visit (UZS) | C10: =Assumptions!C8 -> 100000 | D10: =Assumptions!D8 -> 200000 | E10: =Assumptions!E8 -> 300000 | F10: Assumptions
B11: A. Annual savings from visits (UZS) | C11: =C9*C10 -> 154000000 | D11: =D9*D10 -> 739200000 | E11: =E9*E10 -> 1478400000 | F11: Visits saved x cost per visit
B12: B. Early-detected losses
B13: Number of misused loans | C13: =C6*Assumptions!C11 -> 46.2 | D13: =D6*Assumptions!D11 -> 77 | E13: =E6*Assumptions!E11 -> 107.8 | F13: N x misuse share (3-7%)
B14: Total misused amount (UZS) | C14: =C13*Assumptions!C14 -> 1256640000 | D14: =D13*Assumptions!D14 -> 2094400000 | E14: =E13*Assumptions!E14 -> 2932160000 | F14: Misused loans x average amount (27.2 M, nationwide regional data)
B15: Additional cases caught by Maqsad | C15: =IF(OR(Assumptions!C15="",Assumptions!C17=""),"not entered",C13*MAX(Assumptions!C15-Assumptions!C17,0)) -> not entered | D15: =IF(OR(Assumptions!D15="",Assumptions!D17=""),"not entered",D13*MAX(Assumptions!D15-Assumptions!D17,0)) -> not entered | E15: =IF(OR(Assumptions!E15="",Assumptions!E17=""),"not entered",E13*MAX(Assumptions!E15-Assumptions!E17,0)) -> not entered | F15: Misused loans x (Maqsad recall - measured current-method recall). Enter baseline first.
B16: B. Amount recovered (UZS/year) | C16: =IF(C15="not entered","not entered",C15*Assumptions!C14*Assumptions!C16) -> not entered | D16: =IF(D15="not entered","not entered",D15*Assumptions!D14*Assumptions!D16) -> not entered | E16: =IF(E15="not entered","not entered",E15*Assumptions!E14*Assumptions!E16) -> not entered | F16: Additional cases caught x average amount x recovery share; synthetic recall is not real-world validation.
B17: Warning | C17: =IF(Assumptions!C17="","baseline needed","") -> baseline needed | D17: =IF(Assumptions!D17="","baseline needed","") -> baseline needed | E17: =IF(Assumptions!E17="","baseline needed","") -> baseline needed | F17: Required before using recovered-loss benefit: enter today's measured catch rate in Assumptions row 17.
B18: C. Costs
B19: GPU server / hardware (one-time), selected option | C19: =Infra!C19 -> 142000000 | D19: =Infra!D19 -> 118500000 | E19: =Infra!E19 -> 95000000 | F19: Infra sheet; selector on Assumptions row 49 (default 1 = original GPU server, 0 for rented options)
B20: People, pilot (one-time) | C20: =IF(COUNT(Assumptions!C23,Assumptions!C24,Assumptions!C25)<3,"not entered",Assumptions!C20*Assumptions!C23+Assumptions!C21*Assumptions!C24+Assumptions!C22*Assumptions!C25) -> 84800000 | D20: =IF(COUNT(Assumptions!D23,Assumptions!D24,Assumptions!D25)<3,"not entered",Assumptions!D20*Assumptions!D23+Assumptions!D21*Assumptions!D24+Assumptions!D22*Assumptions!D25) -> 56600000 | E20: =IF(COUNT(Assumptions!E23,Assumptions!E24,Assumptions!E25)<3,"not entered",Assumptions!E20*Assumptions!E23+Assumptions!E21*Assumptions!E24+Assumptions!E22*Assumptions!E25) -> 37800000 | F20: Sum of (hourly rate x hours)
B21: Total one-time cost (UZS) | C21: =IF(C20="not entered","not entered",C19+C20) -> 226800000 | D21: =IF(D20="not entered","not entered",D19+D20) -> 175100000 | E21: =IF(E20="not entered","not entered",E19+E20) -> 132800000 | F21: Server + people
B22: Annual recurring cost, excl. LLM (UZS) | C22: =Assumptions!C27+Assumptions!C28+Infra!C20 -> 72600000 | D22: =Assumptions!D27+Assumptions!D28+Infra!D20 -> 70100000 | E22: =Assumptions!E27+Assumptions!E28+Infra!E20 -> 67600000 | F22: Support + licences/security + hosting of the selected option (hosting is 0 for option 1)
B23: Remote checks per year | C23: =C6*Assumptions!C31 -> 3080 | D23: =D6*Assumptions!D31 -> 4620 | E23: =E6*Assumptions!E31 -> 6160 | F23: N x check frequency
B24: Annual LLM API cost, selected option (UZS) | C24: =Infra!C46 -> 0 | D24: =Infra!D46 -> 0 | E24: =Infra!E46 -> 0 | F24: Infra row 46: 0 for option 1 (local LLM, no API cost); for options 2-3 the external API price (Assumptions row 29, measured tokens x Gemini price)
B25: Total annual recurring cost (UZS) | C25: =C22+C24 -> 72600000 | D25: =D22+D24 -> 70100000 | E25: =E22+E24 -> 67600000
B26: D. Unit economics
B27: Cost per check (UZS) | C27: =IF(C23=0,"not entered",C25/C23) -> 23571.429 | D27: =IF(D23=0,"not entered",D25/D23) -> 15173.16 | E27: =IF(E23=0,"not entered",E25/E23) -> 10974.026 | F27: Annual recurring cost / number of checks (excludes one-time cost)
B28: Comparison: cost per visit (UZS) | C28: =C10 -> 100000 | D28: =D10 -> 200000 | E28: =E10 -> 300000 | F28: Is a Maqsad check cheaper than a visit?
B29: E. Payback
B30: Annual net benefit, visit savings only (UZS) | C30: =C11-C25 -> 81400000 | D30: =D11-D25 -> 669100000 | E30: =E11-E25 -> 1410800000 | F30: A - annual recurring cost (conservative, excludes recovered losses)
B31: Annual net benefit, incl. recovered losses (UZS) | C31: =IF(C16="not entered","not entered",C30+C16) -> not entered | D31: =IF(D16="not entered","not entered",D30+D16) -> not entered | E31: =IF(E16="not entered","not entered",E30+E16) -> not entered | F31: A + B - annual recurring cost
B32: Payback period, months (visit savings only) | C32: =IF(C21="not entered","not entered",IF(C30<=0,"no payback",C21/(C30/12))) -> 33.434889 | D32: =IF(D21="not entered","not entered",IF(D30<=0,"no payback",D21/(D30/12))) -> 3.1403378 | E32: =IF(E21="not entered","not entered",IF(E30<=0,"no payback",E21/(E30/12))) -> 1.1295719 | F32: One-time cost / monthly net benefit
B33: Payback period, months (incl. recovered losses) | C33: =IF(OR(C21="not entered",C31="not entered"),"not entered",IF(C31<=0,"no payback",C21/(C31/12))) -> not entered | D33: =IF(OR(D21="not entered",D31="not entered"),"not entered",IF(D31<=0,"no payback",D21/(D31/12))) -> not entered | E33: =IF(OR(E21="not entered",E31="not entered"),"not entered",IF(E31<=0,"no payback",E21/(E31/12))) -> not entered | F33: One-time cost / monthly net benefit
B35: F. Unit economics, measured CPU cost (cost.md)
B36: Marginal CPU cost per check (UZS, upper bound) | C36: =Infra!C8 -> 0.042599871 | D36: =Infra!D8 -> 0.042599871 | E36: =Infra!E8 -> 0.042599871 | F36: Money-trail + scenario + photo, cloud CPU price. Measured CPU time, public price.
B37: Marginal CPU cost as share of fully loaded cost per check | C37: =IF(ISNUMBER(C27),C36/C27,"not entered") -> 1.8072672e-06 | D37: =IF(ISNUMBER(D27),D36/D27,"not entered") -> 2.8075806e-06 | E37: =IF(ISNUMBER(E27),E36/E27,"not entered") -> 3.8818817e-06 | F37: Shows that cost per check is almost entirely fixed cost (support, licences, hosting), not compute.
B38: One visit costs this many times a fully loaded check | C38: =IF(ISNUMBER(C27),C10/C27,"not entered") -> 4.2424242 | D38: =IF(ISNUMBER(D27),D10/D27,"not entered") -> 13.18117 | E38: =IF(ISNUMBER(E27),E10/E27,"not entered") -> 27.337278 | F38: Visit cost / cost per check (row 27). Both rest on unverified inputs except CPU time.
B39: G. Break-even and pilot budget (visit savings only)
B40: Break-even cost per visit (UZS) | C40: =IF(C9=0,"n/a",C25/C9) -> 47142.857 | D40: =IF(D9=0,"n/a",D25/D9) -> 18966.45 | E40: =IF(E9=0,"n/a",E25/E9) -> 13717.532 | F40: Annual recurring cost / visits saved. Below this visit cost, Maqsad does not pay for itself on visit savings alone.
B41: Break-even visits saved per year | C41: =IF(C10=0,"n/a",C25/C10) -> 726 | D41: =IF(D10=0,"n/a",D25/D10) -> 350.5 | E41: =IF(E10=0,"n/a",E25/E10) -> 225.33333 | F41: Annual recurring cost / cost per visit.
B42: Safety margin: assumed visit cost / break-even visit cost | C42: =IF(ISNUMBER(C40),C10/C40,"n/a") -> 2.1212121 | D42: =IF(ISNUMBER(D40),D10/D40,"n/a") -> 10.544936 | E42: =IF(ISNUMBER(E40),E10/E40,"n/a") -> 21.869822 | F42: Above 1.0x = pays back on visits alone under these (unverified) inputs.
...

Sheet Infra
B1: Infrastructure cost options (measured CPU, cost.md)
B2: Inputs live on Assumptions rows 49-58. Prices are public prices in original currency converted with Assumptions rows 30 and 57. No GPU is needed for the measured prototype; the LLM in production is not yet measured.
B4: Metric | C4: Pessimistic | D4: Base | E4: Optimistic | F4: Formula / note
B5: A. Variable CPU cost per check (Option 3: cloud CPU, Railway)
B6: CPU seconds per check, upper bound (score + scenario + photo) | C6: =Assumptions!C50+Assumptions!C51+Assumptions!C52 -> 0.466 | D6: =Assumptions!D50+Assumptions!D51+Assumptions!D52 -> 0.466 | E6: =Assumptions!E50+Assumptions!E51+Assumptions!E52 -> 0.466 | F6: Taxmin: every remote check runs all three components (upper bound; real mix not measured).
B7: Variable cost per check (USD) | C7: =C6*Assumptions!C54/60 -> 3.5959667e-06 | D7: =D6*Assumptions!D54/60 -> 3.5959667e-06 | E7: =E6*Assumptions!E54/60 -> 3.5959667e-06 | F7: CPU seconds x USD per vCPU-minute / 60 (cost.md section 3 formula).
B8: Variable cost per check (UZS) | C8: =C7*Assumptions!C30 -> 0.042599871 | D8: =D7*Assumptions!D30 -> 0.042599871 | E8: =E7*Assumptions!E30 -> 0.042599871 | F8: USD x exchange rate (Assumptions row 30).
B9: Remote checks per year | C9: =ROI!C23 -> 3080 | D9: =ROI!D23 -> 4620 | E9: =ROI!E23 -> 6160 | F9: From ROI sheet.
B10: Annual variable CPU cost (UZS) | C10: =C9*C8 -> 131.2076 | D10: =D9*D8 -> 196.8114 | E10: =E9*E8 -> 262.4152 | F10: Checks x cost per check. Effectively zero compared with fixed cost items.
B11: Always-on memory cost per month (USD) | C11: =Assumptions!C53/1024*Assumptions!C55 -> 13.935547 | D11: =Assumptions!D53/1024*Assumptions!D55 -> 13.935547 | E11: =Assumptions!E53/1024*Assumptions!E55 -> 13.935547 | F11: MB / 1024 x USD per GB-month. cost.md section 4: USD 11.51.
B12: Annual memory cost (UZS) | C12: =C11*12*Assumptions!C30 -> 1981061.2 | D12: =D11*12*Assumptions!D30 -> 1981061.2 | E12: =E11*12*Assumptions!E30 -> 1981061.2 | F12: 12 months x monthly USD x exchange rate.
B13: Option 3 annual hosting, Railway (UZS) | C13: =C10+C12 -> 1981192.4 | D13: =D10+D12 -> 1981258 | E13: =E10+E12 -> 1981323.6 | F13: Variable CPU + always-on memory. Idle CPU, egress, storage not counted (cost.md section 6).
B14: B. Dedicated CPU server (Option 2: Hetzner AX42)
B15: Option 2 annual hosting, dedicated server (UZS) | C15: =12*Assumptions!C56*Assumptions!C57 -> 10834772 | D15: =12*Assumptions!D56*Assumptions!D57 -> 10834772 | E15: =12*Assumptions!E56*Assumptions!E57 -> 10834772 | F15: Flat monthly price x 12 x EUR rate. Price NOT confirmed on hetzner.com; rate is the 9 Sep 2026 cbu.uz value.
B16: Input check | C16: =IF(OR(Assumptions!C56="",Assumptions!C57=""),"input missing","ok") -> ok | D16: =IF(OR(Assumptions!D56="",Assumptions!D57=""),"input missing","ok") -> ok | E16: =IF(OR(Assumptions!E56="",Assumptions!E57=""),"input missing","ok") -> ok | F16: Flags missing server price or EUR rate.
B17: C. Option selected on Assumptions row 49
B18: Selected option (1 / 2 / 3) | C18: =Assumptions!$C$49 -> 1 | D18: =Assumptions!$C$49 -> 1 | E18: =Assumptions!$C$49 -> 1 | F18: 1 = GPU on-prem (original), 2 = dedicated CPU, 3 = cloud CPU.
B19: One-time hardware, selected option (UZS) | C19: =CHOOSE(C18,Assumptions!C26,0,0) -> 142000000 | D19: =CHOOSE(D18,Assumptions!D26,0,0) -> 118500000 | E19: =CHOOSE(E18,Assumptions!E26,0,0) -> 95000000 | F19: Option 1 uses the original GPU server input (Assumptions row 26); options 2 and 3 are rented, no purchase.
B20: Annual hosting, selected option (UZS) | C20: =CHOOSE(C18,0,C15,C13) -> 0 | D20: =CHOOSE(D18,0,D15,D13) -> 0 | E20: =CHOOSE(E18,0,E15,E13) -> 0 | F20: Option 1 has no hosting line in the original model (0).
B21: D. All options side by side (independent of the selector; visit savings only)
B22: Option 1: GPU on-prem (original assumption)
B23: One-time hardware (UZS) | C23: =Assumptions!C26 -> 142000000 | D23: =Assumptions!D26 -> 118500000 | E23: =Assumptions!E26 -> 95000000
B24: Annual recurring cost incl. LLM (UZS) | C24: =Assumptions!C27+Assumptions!C28+0+0 -> 72600000 | D24: =Assumptions!D27+Assumptions!D28+0+0 -> 70100000 | E24: =Assumptions!E27+Assumptions!E28+0+0 -> 67600000 | F24: Support + licences/security + hosting (0) + LLM API (0: local LLM, option 1).
B25: Annual net benefit, visit savings only (UZS) | C25: =ROI!C11-C24 -> 81400000 | D25: =ROI!D11-D24 -> 669100000 | E25: =ROI!E11-E24 -> 1410800000 | F25: A - annual recurring cost.
B26: Hardware-only payback, months (lower bound) | C26: =IF(C25<=0,"no payback",C23/(C25/12)) -> 20.933661 | D26: =IF(D25<=0,"no payback",D23/(D25/12)) -> 2.1252429 | E26: =IF(E25<=0,"no payback",E23/(E25/12)) -> 0.80805217 | F26: Excludes pilot people cost (hours not entered yet).
B27: Option 2: dedicated CPU server (rental)
B28: One-time hardware (UZS) | C28: =0 -> 0 | D28: =0 -> 0 | E28: =0 -> 0
B29: Annual recurring cost incl. LLM (UZS) | C29: =Assumptions!C27+Assumptions!C28+C15+C45 -> 83890865 | D29: =Assumptions!D27+Assumptions!D28+D15+D45 -> 81310775 | E29: =Assumptions!E27+Assumptions!E28+E15+E45 -> 78685441 | F29: Support + licences/security + hosting + LLM.
B30: Annual net benefit, visit savings only (UZS) | C30: =ROI!C11-C29 -> 70109135 | D30: =ROI!D11-D29 -> 6.5788923e+08 | E30: =ROI!E11-E29 -> 1.3997146e+09 | F30: A - annual recurring cost.
B31: Hardware-only payback, months (lower bound) | C31: =IF(C30<=0,"no payback",C28/(C30/12)) -> 0 | D31: =IF(D30<=0,"no payback",D28/(D30/12)) -> 0 | E31: =IF(E30<=0,"no payback",E28/(E30/12)) -> 0 | F31: Excludes pilot people cost (hours not entered yet).
B32: Option 3: cloud CPU (Railway)
B33: One-time hardware (UZS) | C33: =0 -> 0 | D33: =0 -> 0 | E33: =0 -> 0
B34: Annual recurring cost incl. LLM (UZS) | C34: =Assumptions!C27+Assumptions!C28+C13+C45 -> 75037285 | D34: =Assumptions!D27+Assumptions!D28+D13+D45 -> 72457261 | E34: =Assumptions!E27+Assumptions!E28+E13+E45 -> 69831992 | F34: Support + licences/security + hosting + LLM.
B35: Annual net benefit, visit savings only (UZS) | C35: =ROI!C11-C34 -> 78962715 | D35: =ROI!D11-D34 -> 6.6674274e+08 | E35: =ROI!E11-E34 -> 1.408568e+09 | F35: A - annual recurring cost.
B36: Hardware-only payback, months (lower bound) | C36: =IF(C35<=0,"no payback",C33/(C35/12)) -> 0 | D36: =IF(D35<=0,"no payback",D33/(D35/12)) -> 0 | E36: =IF(E35<=0,"no payback",E33/(E35/12)) -> 0 | F36: Excludes pilot people cost (hours not entered yet).
B37: Limits: development, dashboard hosting, audit log, bank officer time are not in the measured cost (cost.md section 6). Measured CPU times are from one 12-core Intel machine; a cloud vCPU may be slower or faster. Photo check numbers (repo, 11 Oct): 361 ms CPU single thread (cost.md), 280 ms wall on all cores (cost.md), p50 287 ms warm (metrics.md), 363 ms client-side incl. network (metrics_api.md). Use the 361 ms CPU figure for cost and say which figure a latency claim comes from.
B39: Check: reported prototype hosting vs modelled Railway cost
B40: Reported prototype hosting, annual (UZS) | C40: =Assumptions!C71*12*Assumptions!C30 -> 710794.2 | D40: =Assumptions!D71*12*Assumptions!D30 -> 710794.2 | E40: =Assumptions!E71*12*Assumptions!E30 -> 710794.2 | F40: Railway Hobby plan fee USD 5/month x 12 (Oybek). Unverified.
B41: Modelled Option 3 hosting, annual (UZS) | C41: =C13 -> 1981192.4 | D41: =D13 -> 1981258 | E41: =E13 -> 1981323.6 | F41: Memory 1,427 MB x USD 10/GB-month + CPU, from Railway public prices (Infra row 13).
B42: Modelled minus reported (UZS) | C42: =C41-C40 -> 1270398.2 | D42: =D41-D40 -> 1270463.8 | E42: =E41-E40 -> 1270529.4 | F42: If large, check the Railway Usage page: the plan fee alone may not be the full bill.
...

Sheet Sensitivity
B1: Sensitivity (Base case, UZS million)
B2: Axis values in blue can be edited. Everything else is a formula on Base inputs. All inputs behind these tables are unverified assumptions or synthetic measurements.
B4: Table 1. Annual net benefit, visit savings only (UZS mln): visits per loan per year (rows) x cost per visit in UZS (columns)
B5: visits/year \ UZS per visit | C5: 50000 | D5: 100000 | E5: 150000 | F5: 200000 | G5: 250000 | H5: 300000
B6: 2 | C6: =(Assumptions!$D$6*$B6*(1-Assumptions!$D$9)*C$5-(Assumptions!$D$27+Assumptions!$D$28+Infra!$D$20+Assumptions!$D$6*$B6*Assumptions!$D$29*Assumptions!$D$30*(Assumptions!$C$49<>1)))/1000000 -> 53.1 | D6: =(Assumptions!$D$6*$B6*(1-Assumptions!$D$9)*D$5-(Assumptions!$D$27+Assumptions!$D$28+Infra!$D$20+Assumptions!$D$6*$B6*Assumptions!$D$29*Assumptions!$D$30*(Assumptions!$C$49<>1)))/1000000 -> 176.3 | E6: =(Assumptions!$D$6*$B6*(1-Assumptions!$D$9)*E$5-(Assumptions!$D$27+Assumptions!$D$28+Infra!$D$20+Assumptions!$D$6*$B6*Assumptions!$D$29*Assumptions!$D$30*(Assumptions!$C$49<>1)))/1000000 -> 299.5 | F6: =(Assumptions!$D$6*$B6*(1-Assumptions!$D$9)*F$5-(Assumptions!$D$27+Assumptions!$D$28+Infra!$D$20+Assumptions!$D$6*$B6*Assumptions!$D$29*Assumptions!$D$30*(Assumptions!$C$49<>1)))/1000000 -> 422.7 | G6: =(Assumptions!$D$6*$B6*(1-Assumptions!$D$9)*G$5-(Assumptions!$D$27+Assumptions!$D$28+Infra!$D$20+Assumptions!$D$6*$B6*Assumptions!$D$29*Assumptions!$D$30*(Assumptions!$C$49<>1)))/1000000 -> 545.9 | H6: =(Assumptions!$D$6*$B6*(1-Assumptions!$D$9)*H$5-(Assumptions!$D$27+Assumptions!$D$28+Infra!$D$20+Assumptions!$D$6*$B6*Assumptions!$D$29*Assumptions!$D$30*(Assumptions!$C$49<>1)))/1000000 -> 669.1
B7: 3 | C7: =(Assumptions!$D$6*$B7*(1-Assumptions!$D$9)*C$5-(Assumptions!$D$27+Assumptions!$D$28+Infra!$D$20+Assumptions!$D$6*$B7*Assumptions!$D$29*Assumptions!$D$30*(Assumptions!$C$49<>1)))/1000000 -> 114.7 | D7: =(Assumptions!$D$6*$B7*(1-Assumptions!$D$9)*D$5-(Assumptions!$D$27+Assumptions!$D$28+Infra!$D$20+Assumptions!$D$6*$B7*Assumptions!$D$29*Assumptions!$D$30*(Assumptions!$C$49<>1)))/1000000 -> 299.5 | E7: =(Assumptions!$D$6*$B7*(1-Assumptions!$D$9)*E$5-(Assumptions!$D$27+Assumptions!$D$28+Infra!$D$20+Assumptions!$D$6*$B7*Assumptions!$D$29*Assumptions!$D$30*(Assumptions!$C$49<>1)))/1000000 -> 484.3 | F7: =(Assumptions!$D$6*$B7*(1-Assumptions!$D$9)*F$5-(Assumptions!$D$27+Assumptions!$D$28+Infra!$D$20+Assumptions!$D$6*$B7*Assumptions!$D$29*Assumptions!$D$30*(Assumptions!$C$49<>1)))/1000000 -> 669.1 | G7: =(Assumptions!$D$6*$B7*(1-Assumptions!$D$9)*G$5-(Assumptions!$D$27+Assumptions!$D$28+Infra!$D$20+Assumptions!$D$6*$B7*Assumptions!$D$29*Assumptions!$D$30*(Assumptions!$C$49<>1)))/1000000 -> 853.9 | H7: =(Assumptions!$D$6*$B7*(1-Assumptions!$D$9)*H$5-(Assumptions!$D$27+Assumptions!$D$28+Infra!$D$20+Assumptions!$D$6*$B7*Assumptions!$D$29*Assumptions!$D$30*(Assumptions!$C$49<>1)))/1000000 -> 1038.7
B8: 4 | C8: =(Assumptions!$D$6*$B8*(1-Assumptions!$D$9)*C$5-(Assumptions!$D$27+Assumptions!$D$28+Infra!$D$20+Assumptions!$D$6*$B8*Assumptions!$D$29*Assumptions!$D$30*(Assumptions!$C$49<>1)))/1000000 -> 176.3 | D8: =(Assumptions!$D$6*$B8*(1-Assumptions!$D$9)*D$5-(Assumptions!$D$27+Assumptions!$D$28+Infra!$D$20+Assumptions!$D$6*$B8*Assumptions!$D$29*Assumptions!$D$30*(Assumptions!$C$49<>1)))/1000000 -> 422.7 | E8: =(Assumptions!$D$6*$B8*(1-Assumptions!$D$9)*E$5-(Assumptions!$D$27+Assumptions!$D$28+Infra!$D$20+Assumptions!$D$6*$B8*Assumptions!$D$29*Assumptions!$D$30*(Assumptions!$C$49<>1)))/1000000 -> 669.1 | F8: =(Assumptions!$D$6*$B8*(1-Assumptions!$D$9)*F$5-(Assumptions!$D$27+Assumptions!$D$28+Infra!$D$20+Assumptions!$D$6*$B8*Assumptions!$D$29*Assumptions!$D$30*(Assumptions!$C$49<>1)))/1000000 -> 915.5 | G8: =(Assumptions!$D$6*$B8*(1-Assumptions!$D$9)*G$5-(Assumptions!$D$27+Assumptions!$D$28+Infra!$D$20+Assumptions!$D$6*$B8*Assumptions!$D$29*Assumptions!$D$30*(Assumptions!$C$49<>1)))/1000000 -> 1161.9 | H8: =(Assumptions!$D$6*$B8*(1-Assumptions!$D$9)*H$5-(Assumptions!$D$27+Assumptions!$D$28+Infra!$D$20+Assumptions!$D$6*$B8*Assumptions!$D$29*Assumptions!$D$30*(Assumptions!$C$49<>1)))/1000000 -> 1408.3
B9: Grid points: 100k and 300k and 2-4 visits are the assumed range (Taxmin, unverified); 150k and 250k are interpolation; 50k is a stress case below that range. Recurring cost follows the selected infrastructure option and adds an LLM API part (options 2-3 only) that scales with visits.
B11: Table 2. Loss benefit vs simple rule (UZS mln): share of misused loans (rows) x share of amount recovered (columns); Base recall, N from Assumptions
B12: misused share \ recovery share | C12: 0.25 | D12: 0.5 | E12: 0.75 | F12: 1
B13: 0.03 | C13: =Assumptions!$D$6*$B13*Assumptions!$D$14*MAX(Assumptions!$D$15-Assumptions!$D$35,0)*C$12/1000000 -> 159.59328 | D13: =Assumptions!$D$6*$B13*Assumptions!$D$14*MAX(Assumptions!$D$15-Assumptions!$D$35,0)*D$12/1000000 -> 319.18656 | E13: =Assumptions!$D$6*$B13*Assumptions!$D$14*MAX(Assumptions!$D$15-Assumptions!$D$35,0)*E$12/1000000 -> 478.77984 | F13: =Assumptions!$D$6*$B13*Assumptions!$D$14*MAX(Assumptions!$D$15-Assumptions!$D$35,0)*F$12/1000000 -> 638.37312
B14: 0.05 | C14: =Assumptions!$D$6*$B14*Assumptions!$D$14*MAX(Assumptions!$D$15-Assumptions!$D$35,0)*C$12/1000000 -> 265.9888 | D14: =Assumptions!$D$6*$B14*Assumptions!$D$14*MAX(Assumptions!$D$15-Assumptions!$D$35,0)*D$12/1000000 -> 531.9776 | E14: =Assumptions!$D$6*$B14*Assumptions!$D$14*MAX(Assumptions!$D$15-Assumptions!$D$35,0)*E$12/1000000 -> 797.9664 | F14: =Assumptions!$D$6*$B14*Assumptions!$D$14*MAX(Assumptions!$D$15-Assumptions!$D$35,0)*F$12/1000000 -> 1063.9552
B15: 0.07 | C15: =Assumptions!$D$6*$B15*Assumptions!$D$14*MAX(Assumptions!$D$15-Assumptions!$D$35,0)*C$12/1000000 -> 372.38432 | D15: =Assumptions!$D$6*$B15*Assumptions!$D$14*MAX(Assumptions!$D$15-Assumptions!$D$35,0)*D$12/1000000 -> 744.76864 | E15: =Assumptions!$D$6*$B15*Assumptions!$D$14*MAX(Assumptions!$D$15-Assumptions!$D$35,0)*E$12/1000000 -> 1117.153 | F15: =Assumptions!$D$6*$B15*Assumptions!$D$14*MAX(Assumptions!$D$15-Assumptions!$D$35,0)*F$12/1000000 -> 1489.5373
B16: 0.13 | C16: =Assumptions!$D$6*$B16*Assumptions!$D$14*MAX(Assumptions!$D$15-Assumptions!$D$35,0)*C$12/1000000 -> 691.57088 | D16: =Assumptions!$D$6*$B16*Assumptions!$D$14*MAX(Assumptions!$D$15-Assumptions!$D$35,0)*D$12/1000000 -> 1383.1418 | E16: =Assumptions!$D$6*$B16*Assumptions!$D$14*MAX(Assumptions!$D$15-Assumptions!$D$35,0)*E$12/1000000 -> 2074.7126 | F16: =Assumptions!$D$6*$B16*Assumptions!$D$14*MAX(Assumptions!$D$15-Assumptions!$D$35,0)*F$12/1000000 -> 2766.2835
B17: 3-7% is the assumed range (Taxmin, unverified); 13% is the fraud share of the synthetic dev split, not a real portfolio rate. 25/50/75% recovery are stress cases (100% is an upper bound). Baseline = simple rule 27.4% (synthetic), not the bank's method.
B19: Table 3. Base case vs share of loans still visited in person (visit savings only)
B20: share visited in person | C20: annual net benefit (UZS mln) | D20: payback (months, incl. pilot people cost)
B21: 0.2 | C21: =(Assumptions!$D$6*Assumptions!$D$7*(1-$B21)*Assumptions!$D$8-ROI!$D$25)/1000000 -> 669.1 | D21: =IF(ISNUMBER(ROI!$D$21),IF(C21<=0,"no payback",ROI!$D$21/(C21*1000000/12)),"not entered") -> 3.1403378
B22: 0.3 | C22: =(Assumptions!$D$6*Assumptions!$D$7*(1-$B22)*Assumptions!$D$8-ROI!$D$25)/1000000 -> 576.7 | D22: =IF(ISNUMBER(ROI!$D$21),IF(C22<=0,"no payback",ROI!$D$21/(C22*1000000/12)),"not entered") -> 3.6434888
B23: 0.4 | C23: =(Assumptions!$D$6*Assumptions!$D$7*(1-$B23)*Assumptions!$D$8-ROI!$D$25)/1000000 -> 484.3 | D23: =IF(ISNUMBER(ROI!$D$21),IF(C23<=0,"no payback",ROI!$D$21/(C23*1000000/12)),"not entered") -> 4.3386331
B24: 0.5 | C24: =(Assumptions!$D$6*Assumptions!$D$7*(1-$B24)*Assumptions!$D$8-ROI!$D$25)/1000000 -> 391.9 | D24: =IF(ISNUMBER(ROI!$D$21),IF(C24<=0,"no payback",ROI!$D$21/(C24*1000000/12)),"not entered") -> 5.3615718
B25: 0.6 | C25: =(Assumptions!$D$6*Assumptions!$D$7*(1-$B25)*Assumptions!$D$8-ROI!$D$25)/1000000 -> 299.5 | D25: =IF(ISNUMBER(ROI!$D$21),IF(C25<=0,"no payback",ROI!$D$21/(C25*1000000/12)),"not entered") -> 7.0156928
B26: Base inputs (Assumptions column D). 20% = brief's visit budget; 50% = pessimistic regulator case. Shares above 20% would also raise the catch rate, but that is not measured, so no loss benefit is added.

Sheet Sample check
B1: Sample cross-check (sample_loans.xlsx, synthetic)
B2: 10 synthetic loans for illustration only. Too few and deliberately mixed (half fraud-labelled) to estimate any rate; used only to compare loan sizes with the 27.2 M UZS average misused amount.
B4: Loan ID | C4: Label (generator) | D4: Loan amount (UZS) | E4: Invoice amount (UZS)
B5: L000266 | C5: halol | D5: 49400000 | E5: 49700000
B6: L003592 | C6: halol | D6: 27100000 | E6: 27800000
B7: L002966 | C7: halol | D7: 58200000 | E7: 58500000
B8: L002235 | C8: halol | D8: 41900000 | E8: 41300000
B9: L002211 | C9: halol | D9: 99400000 | E9: 91200000
B10: L003933 | C10: T1 | D10: 28600000 | E10: 29700000
B11: L000387 | C11: T2 | D11: 33900000 | E11: 32600000
B12: L003795 | C12: T3 | D12: 99200000 | E12: 97100000
B13: L001568 | C13: T4 | D13: 114300000 | E13: 108900000
B14: L001289 | C14: T1 | D14: 48400000 | E14: 46800000
B16: Loans in sample | C16: =COUNTA(B5:B14) -> 10
B17: Fraud-labelled loans in sample | C17: =COUNTIF(C5:C14,"<>halol") -> 5
B18: Average loan amount, all (UZS) | C18: =AVERAGE(D5:D14) -> 60040000
B19: Average loan amount, fraud-labelled (UZS) | C19: =AVERAGEIF(C5:C14,"<>halol",D5:D14) -> 64880000
B20: Average misused amount per case in ROI model (UZS) | C20: =Assumptions!D14 -> 27200000
B21: Model misused amount / sample average loan | C21: =IF(C18=0,"n/a",C20/C18) -> 0.45303131
B22: Reading: the 27.2 M UZS per case (anhor.uz, nationwide regional inspections) is below typical loan sizes in the synthetic sample, so the model does not assume that a whole loan is lost. The synthetic loan sizes themselves are not a source for real MKBANK loans.

Sheet Deck summary
B1: Deck summary (all values are formulas from the ROI sheet; one-branch pilot)
B2: Every input is an assumption marked 'Taxmin' unless stated.
B4: Metric | C4: Pessimistic | D4: Base | E4: Optimistic
B5: Loans monitored in the pilot branch | C5: =ROI!C6 -> 1540 | D5: =ROI!D6 -> 1540 | E5: =ROI!E6 -> 1540
B6: Visits saved per year | C6: =ROI!C9 -> 1540 | D6: =ROI!D9 -> 3696 | E6: =ROI!E9 -> 4928
B7: Annual savings from visits (UZS mln) | C7: =ROI!C11/1000000 -> 154 | D7: =ROI!D11/1000000 -> 739.2 | E7: =ROI!E11/1000000 -> 1478.4
B8: Annual recurring cost (UZS mln) | C8: =ROI!C25/1000000 -> 72.6 | D8: =ROI!D25/1000000 -> 70.1 | E8: =ROI!E25/1000000 -> 67.6
B9: Annual net benefit, visit savings only (UZS mln) | C9: =ROI!C30/1000000 -> 81.4 | D9: =ROI!D30/1000000 -> 669.1 | E9: =ROI!E30/1000000 -> 1410.8
B10: One-time cost: hardware + pilot people (UZS mln) | C10: =IF(ISNUMBER(ROI!C21),ROI!C21/1000000,ROI!C21) -> 226.8 | D10: =IF(ISNUMBER(ROI!D21),ROI!D21/1000000,ROI!D21) -> 175.1 | E10: =IF(ISNUMBER(ROI!E21),ROI!E21/1000000,ROI!E21) -> 132.8
B11: Payback (months), visit savings only | C11: =ROI!C32 -> 33.434889 | D11: =ROI!D32 -> 3.1403378 | E11: =ROI!E32 -> 1.1295719
B12: Cost per remote check (UZS) | C12: =ROI!C27 -> 23571.429 | D12: =ROI!D27 -> 15173.16 | E12: =ROI!E27 -> 10974.026
B13: Cost per physical visit (UZS) | C13: =ROI!C28 -> 100000 | D13: =ROI!D28 -> 200000 | E13: =ROI!E28 -> 300000
B14: Model catch rate at 20% visit budget (synthetic holdout) | C14: =Assumptions!C15 -> 0.728 | D14: =Assumptions!D15 -> 0.782 | E14: =Assumptions!E15 -> 0.832
B16: Not included: recovered misused amounts (needs today's catch rate, measured in pilot month 1) and penalties.
B17: Catch rate is measured on synthetic data; real accuracy is measured on the bank's historical loans in pilot month 1.
